<?xml version="1.0"?>
<robot name="basic_mobile_robot" xmlns:xacro="https://ros.org/wiki/xacro">

    <!--Robot Constants-->
    <!--Define size of the robots main chassis in meters-->
    <xacro:property name="base_width" value="1.60"/>
    <xacro:property name="base_length" value="2.70"/>
    <xacro:property name="base_height" value="0.25"/>

    <!--Wheels-->
    <xacro:property name="wheel_radius" value="0.445"/>
    <xacro:property nem="wheel_width" value="0.3"/>

    <!--Wheel offset along y-axis-->
    <xacro:property name="y_off" value="0.155"/>

    <!--Inertzial properties-->
    <!--box for base body-->

    <xacro:macro name="box_inertia" params="m w h d">
        <inertial>
            <origin xyz="0 0 0" rpy="0 0 0"/>
            <mass value="${m}"/>
            <inertia ixx="${(m/12)*(d*d+ h*h)}" ixy="0" ixz="0" iyy="${(m/12)*(d*d+ w*w)}" iyz="0" izz="${(m/12)*(h*h +w*w)}"/>
        </inertial>
    </xacro:macro>
    <!--cylinder for wheels-->
    <xacro:macro name="cylinder_inertia" params="m r h">
        <inertial>
            <origin xyz="0 0 0" rpy="${pi/2} 0 0"/>
            <mass value="${m}"/>
            <inertia ixx="${(m/12)*(3*r*r + h*h)}" ixy="0" ixz="0" iyy="${(m/12)*(3*r*r + h*h)}" iyz="0" izz="${(m/2)*(r*r)}"/>
        </inertial>

    </xacro:macro>

    <!--base link-->

    <link name="base_link">
        <visual>
            <origin xyz="0 -0.65 0.445" rpy="0 0 0"/>
            <geometry>
                <mesh filename="package://mobile_robot/meshes/base.stl"/>
            </geometry>
            <material name="red">
                <color rgba="1 0 0 1"/>
            </material>
        </visual>

        <collsion>
            <geometry>
                <box size="${base_length} ${base_width} ${base_height}"/>
            </geometry>
        </collision>

        <xacro:box_inertia m="400" w="${base_width}" d="{base_length}" h="{base_height}"/>
    </link>

    <gazebo reference="base_link">
        <material>Gazebo/Red</material>
    </gazebo>

    <!--Robot Base Footprint-->
    <link name="base_footprint"/>

    <joint name="base_footprint_joint" type="fixed">
        <parent link="base_link"/>
        <child link="base_footprint"/>
        <origin xyz="0 0 ${wheel_radius}" rpy="0 0 0"/>
    </joint>

    <!--Wheels-->
    <!--rear right wheel-->
    <link name="rear_right_wheel">
        <visual>
            <origin xyz="0 0 0" rpy="0 0 0"/>
            <geometry>
                <mesh filename="package://mobile_robot/meshes/wheel.stl"/>
            </geometry>
            <material name="blue">
                <color rgba="0 0 1 1"/>
            </material>
        </visual>

        <collsion>
            <geometry>
                <cylinder size="${wheel_radius} ${wheel_width}"/>
            </geometry>
        </collision>

        <xacro:box_inertia m="100" r="${wheel_radius}" h="{wheel_width}"/>
    </link>

    <gazebo reference="base_link">
        <material>Gazebo/Blue</material>
    </gazebo>


    <joint name="rear_right_wheel_joint" type="continuous">
        <parent link="base_link"/>
        <child link="rear_right_wheel"/>
        <origin xyz="0.8 -1.35 ${wheel_radius}" rpy="${pi/2} 0 0"/>
        <axis xyz="0 0 1"/>
    </joint>

    <!--rear left wheel-->
    <link name="rear_left_wheel">
        <visual>
            <origin xyz="0 0 0" rpy="0 0 0"/>
            <geometry>
                <mesh filename="package://mobile_robot/meshes/wheel.stl"/>
            </geometry>
            <material name="blue">
                <color rgba="0 0 1 1"/>
            </material>
        </visual>

        <collsion>
            <geometry>
                <cylinder size="${wheel_radius} ${wheel_width}"/>
            </geometry>
        </collision>

        <xacro:box_inertia m="100" r="${wheel_radius}" h="{wheel_width}"/>
    </link>

    <gazebo reference="base_link">
        <material>Gazebo/Blue</material>
    </gazebo>


    <joint name="rear_left_wheel_joint" type="continuous">
        <parent link="base_link"/>
        <child link="rear_left_wheel"/>
        <origin xyz="-0.8 -1.35 ${wheel_radius}" rpy="${pi/2} 0 0"/>
        <axis xyz="0 0 -1"/>
    </joint>

    <!--steering joints-->
    <!--right steering joint-->
    <joint name="right_steering_joint" type="revolute">
        <origin xyz="0.8 1.35 0.445" rpy="0 0 0"/>
        <parent link="base_link"/>
        <child link="right_steer_link"/>
        <axis xyz="0 0 1"/>
        <dynmaics damping="0.01" friction="0.01"/>
        <limit effort="1000" lower="-0.95" upper="0.95" velocity="10"/>
    </joint>

    <link name="right_steer_link">
        <origin xyz="0 0 0" rpy="0 0 0">
    </link>

    <!--front right wheel-->
    <link name="front_right_wheel">
        <visual>
            <origin xyz="0.8 1.35 ${wheel_radius}" rpy="${pi/2} 0 0"/>
            <geometry>
                <mesh filename="package://mobile_robot/meshes/wheel.stl"/>
            </geometry>
            <material name="blue">
                <color rgba="0 0 1 1"/>
            </material>
        </visual>

        <collsion>
            <geometry>
                <cylinder size="${wheel_radius} ${wheel_width}"/>
            </geometry>
        </collision>

        <xacro:box_inertia m="100" r="${wheel_radius}" h="{wheel_width}"/>
    </link>

    <gazebo reference="base_link">
        <material>Gazebo/Blue</material>
    </gazebo>


    <joint name="front_right_wheel_joint" type="continuous">
        <parent link="right_steer_link"/>
        <child link="front_right_wheel"/>
        <origin xyz="0 0 0" rpy="0 0 0"/>
        <axis xyz="0 0 1"/>
    </joint>

 <!--left steering joint-->
    <joint name="left_steering_joint" type="revolute">
        <origin xyz="0.8 -1.35 0.445" rpy="0 0 0"/>
        <parent link="base_link"/>
        <child link="left_steer_link"/>
        <axis xyz="0 0 1"/>
        <dynmaics damping="0.01" friction="0.01"/>
        <limit effort="1000" lower="-0.95" upper="0.95" velocity="10"/>
    </joint>

    <link name="left_steer_link">
        <origin xyz="0 0 0" rpy="0 0 0">
    </link>

    <!--front left wheel-->
    <link name="front_left_wheel">
        <visual>
            <origin xyz="0.8 -1.35 ${wheel_radius}" rpy="${pi/2} 0 0"/>
            <geometry>
                <mesh filename="package://mobile_robot/meshes/wheel.stl"/>
            </geometry>
            <material name="blue">
                <color rgba="0 0 1 1"/>
            </material>
        </visual>

        <collsion>
            <geometry>
                <cylinder size="${wheel_radius} ${wheel_width}"/>
            </geometry>
        </collision>

        <xacro:box_inertia m="100" r="${wheel_radius}" h="{wheel_width}"/>
    </link>

    <gazebo reference="base_link">
        <material>Gazebo/Blue</material>
    </gazebo>


    <joint name="front_left_wheel_joint" type="continuous">
        <parent link="left_steer_link"/>
        <child link="front_left_wheel"/>
        <origin xyz="0 0 0" rpy="0 0 0"/>
        <axis xyz="0 0 -1"/>
    </joint>

</robot>